<?xml version="1.0"?>
<robot name="auto_robot" 
xmlns:sensor="http://playerstage.sourceforge.net/gazebo/xmlschema/#sensor"
    xmlns:controller="http://playerstage.sourceforge.net/gazebo/xmlschema/#controller"
    xmlns:interface="http://playerstage.sourceforge.net/gazebo/xmlschema/#interface">

<xacro:include filename="$(find hector_sensors_description)/urdf/hokuyo_utm30lx.urdf.xacro"/>
	<link name="base_link">
		<visual>

			<geometry>

				<mesh filename="package://teleop_description/mesh/auto_base.DAE"/>

 				<box size="0.6 .2 .1"/>
			
			</geometry>
			<origin xyz="0 0 0" rpy="1.57075 0 0"/>
			<material name="blue">
           			<color rgba="0 0 .8 1"/>
  		       </material>
		</visual>
	</link>

	<link name="LFrontLeg_link">
		<visual>
			<geometry>
				<mesh filename="package://teleop_description/mesh/auto_FrontLeg.DAE"/>
			</geometry>
			<origin xyz="0 0.085 0" rpy="1.57075 0 0"/>
			<material name="white">
           			<color rgba="1 1 1 1"/>
  		       </material>
		</visual>
	</link>

	<link name="LBackLeg_link">
		<visual>
			<geometry>
				<mesh filename="package://teleop_description/mesh/auto_BackLeg.DAE"/>
			</geometry>
			
			<origin xyz="0 0.085 0" rpy="1.57075 0 0"/>
			<material name="white">
           			<color rgba="1 1 1 1"/>
  		       </material>
		</visual>
	</link>

	<link name="RFrontLeg_link">
		<visual>
			<geometry>
				<mesh filename="package://teleop_description/mesh/auto_FrontLeg.DAE"/>
			</geometry>
			
			<origin xyz="0 0 0" rpy="1.57075 0 0"/>
			<material name="white">
           			<color rgba="1 1 1 1"/>
  		       </material>
		</visual>
	</link>

	<link name="RBackLeg_link">
		<visual>
			<geometry>
				<mesh filename="package://teleop_description/mesh/auto_BackLeg.DAE"/>
			</geometry>
			
			<origin xyz="0 0 0" rpy="1.57075 0 0"/>
			<material name="white">
           			<color rgba="1 1 1 1"/>
  		       </material>
		</visual>
	</link>

<link name="top_link">
		<visual>
			<geometry>
				<mesh filename="package://teleop_description/mesh/auto_top.DAE"/>
			</geometry>
			<origin xyz="0 0 0" rpy="1.57075 0 0"/>
		<material name="red">
           			<color rgba="0.8 0 0 1"/>
   			</material>
		</visual>
	</link>



	<link name="mani0_link">
		<visual>
			<geometry>
				<mesh filename="package://teleop_description/mesh/auto_mani0.DAE"/>
			</geometry>
			<origin xyz="0 0 0" rpy="1.57075 0 0"/>
		</visual>
	</link>

	<link name="mani1_link">
		<visual>
			<geometry>
				<mesh filename="package://teleop_description/mesh/auto_mani1.DAE"/>
			</geometry>
			<origin xyz="0 0 0" rpy="1.57075 0.143 0"/>
		</visual>
	</link>

	<link name="mani2_link">
		<visual>
			<geometry>
				<mesh filename="package://teleop_description/mesh/auto_mani2.DAE"/>
			</geometry>
			<origin xyz="0 0 0" rpy="1.57075 -0.4957 0"/>
		</visual>
	</link>
	<link name="mani3_link">
		<visual>
			<geometry>
				<mesh filename="package://teleop_description/mesh/auto_mani3.DAE"/>
			</geometry>
			<origin xyz="0 0 0.007" rpy="1.57075 0 0"/>
		</visual>
	</link>

	<link name="mani4_link">
		<visual>
			<geometry>
				<mesh filename="package://teleop_description/mesh/auto_mani4.DAE"/>
			</geometry>
			<origin xyz="0 0 0.007" rpy="1.57075 0 0"/>
		</visual>
	</link>

	<link name="mani5_link">
		<visual>
			<geometry>
				<mesh filename="package://teleop_description/mesh/auto_mani5.DAE"/>
			</geometry>
			<origin xyz="0 0 0" rpy="1.57075 0 0"/>
		</visual>
	</link>

	<link name="endeffector_link">
		<visual>
			<geometry>
				<mesh filename="package://teleop_description/mesh/auto_endeffector.DAE"/>
			</geometry>
			<origin xyz="0 0 0" rpy="1.57075 0 0"/>
		</visual>
	</link>

	
	<joint name="LFrontLeg_joint" type="continuous">
		<parent link="base_link"/>
		<child link="LFrontLeg_link"/>
		<origin xyz="0.203 0.178 -0.075" rpy="0 0 0"/>
		<axis xyz="0 1 0"/>
	</joint>

	<joint name="LBackLeg_joint" type="continuous">
		<parent link="base_link"/>
		<child link="LBackLeg_link"/>
		<origin xyz="-0.203 0.178 -0.075" rpy="0 0 0"/>	
		<axis xyz="0 1 0"/>
	</joint>

	<joint name="RFrontLeg_joint" type="continuous">
		<parent link="base_link"/>
		<child link="RFrontLeg_link"/>
		<origin xyz="0.203 -0.178 -0.075" rpy="0 0 0"/>
		<axis xyz="0 1 0"/>			
	</joint>

	<joint name="RBackLeg_joint" type="continuous">
		<parent link="base_link"/>
		<child link="RBackLeg_link"/>
		<origin xyz="-0.203 -0.178 -0.075" rpy="0 0 0"/>
		<axis xyz="0 1 0"/>
	</joint>

<joint name="top_joint" type="fixed">
		<parent link="base_link"/>
		<child link="top_link"/>
		<origin xyz="0 0 0" rpy="0 0 0"/>
	</joint>

	<joint name="mani0_joint" type="continuous">
		<parent link="base_link"/>
		<child link="mani0_link"/>
		<origin xyz="0.1885 0 0" rpy="0 0 0"/>
		<axis xyz="0 0 1"/>
	</joint>

	<joint name="mani1_joint" type="continuous">
		<parent link="mani0_link"/>
		<child link="mani1_link"/>
		<origin xyz="0 0 0.145" rpy="0 0 0"/>
		<axis xyz="0 1 0"/>
	</joint>

	<joint name="mani2_joint" type="continuous">
		<parent link="mani1_link"/>
		<child link="mani2_link"/>
		<origin xyz="-0.36 0 0.08" rpy="0 0 0"/>
		<axis xyz="0 1 0"/>
	</joint>

	<joint name="mani3_joint" type="fixed">
		<parent link="mani2_link"/>
		<child link="mani3_link"/>
		<origin xyz="0.05 0 0.015" rpy="0 0 0"/>
	</joint>

	<joint name="mani4_joint" type="prismatic">
		<parent link="mani3_link"/>
		<child link="mani4_link"/>
		<origin xyz="0.391 0 0" rpy="0 0 0"/>
		<limit effort="1000.0" lower="0.18" upper="0" velocity="0.5"/>
	</joint>

	<joint name="mani5_joint" type="continuous">
		<parent link="mani4_link"/>
		<child link="mani5_link"/>
		<origin xyz="0 0 0" rpy="0 0 0"/>
		<axis xyz="1 0 0"/>
	</joint>

	<joint name="endeffector_joint" type="continuous">
		<parent link="mani5_link"/>
		<child link="endeffector_link"/>
		<origin xyz="0.09 0 0" rpy="0 0 0"/>
		<axis xyz="0 1 0"/>
	</joint>

 <sensor name="temp" update_rate="20">
   <parent link="endeffector_link"/>
   <origin xyz="0 0 0" rpy="0 0 0"/>
  
 </sensor>
</robot>
